#VRML_SIM R2023b utf8

EXTERNPROTO "https://raw.githubusercontent.com/cyberbotics/webots/R2023b/projects/objects/backgrounds/protos/TexturedBackground.proto"
EXTERNPROTO "https://raw.githubusercontent.com/cyberbotics/webots/R2023b/projects/objects/backgrounds/protos/TexturedBackgroundLight.proto"
EXTERNPROTO "https://raw.githubusercontent.com/cyberbotics/webots/R2023b/projects/objects/floors/protos/RectangleArena.proto"
EXTERNPROTO "../protos/PlanterBox.proto"
EXTERNPROTO "../protos/Robotiq2f140Gripper.proto"

WorldInfo {
}
Viewpoint {
  orientation 0.24935943426542195 0.27396442983923736 -0.9288505604916705 1.5504908808607116
  position -0.21532389082786288 15.46029913551251 11.92842485635083
}
TexturedBackground {
}
TexturedBackgroundLight {
}
RectangleArena {
  floorSize 200 200
  floorTileSize 10 10
}
Robot {
  translation 0 -0.5 1.33
  rotation 1 0 0 1.5708
  children [
    DEF arm Group {
      children [
        SliderJoint {
          jointParameters JointParameters {
            position -2.499999999999999
            axis 0 1 0
          }
          device [
            LinearMotor {
              name "lmY"
            }
          ]
          endPoint Solid {
            translation 0 -2.499999999999999 -0.02
            children [
              HingeJoint {
                jointParameters HingeJointParameters {
                  axis 0 0 1
                }
                device [
                  RotationalMotor {
                    name "rm"
                  }
                ]
                endPoint Solid {
                  translation 0.7 2.99 0
                  rotation 0 0 1 1.5708
                  children [
                    Robotiq2f140Gripper {
                      hidden position_0_0 -0.003918331264833446
                      hidden position_0_1 -0.0020916015683564056
                      hidden position_0_2 -0.0038946406138587334
                      hidden position_0_3 -0.0021681851508898353
                      hidden linearVelocity_0 2.5635140667044376e-05 2.2520979223397456e-08 0.004877621270955867
                      hidden angularVelocity_0 5.366368152952346e-06 0.000865973655480558 -1.9924077294677255e-08
                      hidden rotation_1 1 0 0 2.2997143312648225
                      hidden linearVelocity_1 -2.888047694202266e-05 4.0086278469751004e-05 0.006167111455859142
                      hidden angularVelocity_1 -6.71942403101328e-05 0.0010425512361449728 -0.0016114204121591078
                      hidden position_2_0 -0.005556075463873291
                      hidden rotation_3 -1 0 0 0.7305560748661417
                      hidden linearVelocity_3 -0.00014490612443079047 -4.949247358236306e-06 0.006417839720303554
                      hidden angularVelocity_3 -5.647668419751362e-05 0.0010545313638072131 -0.0006667719190849742
                      hidden rotation_5 1 0 0 2.293704398431637
                      hidden position_5_0 -0.0013854530550063522
                      hidden linearVelocity_5 3.2990394851894495e-05 3.8054157802127095e-06 0.00613535871008172
                      hidden angularVelocity_5 -4.923309482144961e-05 0.0010560066368263095 6.633713279829643e-05
                      hidden rotation_6 3.372856018413806e-10 0.9127007592037142 0.40862858949046105 3.141592999999343
                      hidden linearVelocity_6 -2.906814255012702e-05 -3.995164489594239e-05 0.006171735653331887
                      hidden angularVelocity_6 8.024332010590397e-05 0.0010429976114603612 0.0016109495245049843
                      hidden position_7_0 -0.005554559305618868
                      hidden translation_8 0 0.08175488890940712 -0.028219999691469624
                      hidden rotation_8 -1 0 0 0.7305545582079421
                      hidden linearVelocity_8 -0.00014553110854362338 6.277199562047205e-06 0.006427735397586308
                      hidden angularVelocity_8 6.979770188273758e-05 0.0010553030825413891 0.0006722806839488245
                      hidden rotation_10 -1.8777032969805693e-10 -0.911457845518422 -0.4113934805547077 3.1415929999997965
                      hidden position_10_0 -0.0014366546099531718
                      hidden linearVelocity_10 3.30108977959936e-05 -4.347528578243943e-06 0.006151199568190712
                      hidden angularVelocity_10 6.283110156039217e-05 0.0010570493602444892 -5.167778798444668e-05
                      translation 0.19347401426750888 0.35040797037933774 -0.5200047885273337
                      rotation 0.9999760290834819 -0.00485294618116267 0.004938640682830686 -1.5708141428175315
                    }
                    Transform {
                      translation -1e-06 0.0599991 -0.520002
                      rotation 0.5773489358556708 -0.5773509358554485 0.5773509358554485 2.0944
                      scale 2 2 6
                      children [
                        Shape {
                          appearance PBRAppearance {
                          }
                          geometry Cylinder {
                            height 0.1
                            radius 0.05
                          }
                        }
                      ]
                    }
                  ]
                  name "wrist"
                }
              }
              Transform {
                translation 0.7 8 -0.53
                scale 10 20 10
                children [
                  Shape {
                    appearance PBRAppearance {
                      baseColor 0.698039 0.698039 0.698039
                    }
                    geometry Mesh {
                      url [
                        "../resource/alum_profiles/50x50 long.dae"
                      ]
                    }
                  }
                ]
              }
            ]
            name "arm"
          }
        }
      ]
    }
    DEF frame Group {
      children [
        Transform {
          translation -0.03 8.75 0
          rotation 0 0 1 -1.5707953071795862
          scale 10 29 10
          children [
            Shape {
              appearance PBRAppearance {
                baseColor 0.698039 0.698039 0.698039
              }
              geometry Mesh {
                url [
                  "../resource/alum_profiles/50x50 long.dae"
                ]
              }
            }
          ]
        }
        Transform {
          translation 7 3.65 0
          scale 10 20 10
          children [
            Shape {
              appearance PBRAppearance {
                baseColor 0.698039 0.698039 0.698039
              }
              geometry Mesh {
                url [
                  "../resource/alum_profiles/50x50 long.dae"
                ]
              }
            }
          ]
        }
        Transform {
          translation -7 3.65 0
          scale 10 20 10
          children [
            Shape {
              appearance PBRAppearance {
                baseColor 0.698039 0.698039 0.698039
              }
              geometry Mesh {
                url [
                  "../resource/alum_profiles/50x50 long.dae"
                ]
              }
            }
          ]
        }
      ]
    }
  ]
  controller "armY"
}
DEF carrot Transform {
  translation 0 0.05 1.55
  rotation 1 0 0 1.5708
  scale 0.4 0.4 0.4
  children [
    Shape {
      appearance PBRAppearance {
        baseColor 0 0 0
      }
      geometry Mesh {
        url [
          "../resource/carrot_model.obj"
        ]
      }
      castShadows FALSE
    }
  ]
}
PlanterBox {
  translation 0 0 1.1
}
