#VRML_SIM R2023b utf8

EXTERNPROTO "https://raw.githubusercontent.com/cyberbotics/webots/R2022b/projects/objects/backgrounds/protos/TexturedBackground.proto"
EXTERNPROTO "https://raw.githubusercontent.com/cyberbotics/webots/R2022b/projects/objects/backgrounds/protos/TexturedBackgroundLight.proto"
EXTERNPROTO "/home/tjacobs/ros2_ws/install/agrobot_pkg/share/agrobot_pkg/protos/PlanterBox.proto"
EXTERNPROTO "https://raw.githubusercontent.com/cyberbotics/webots/released/projects/objects/floors/protos/RectangleArena.proto"

WorldInfo {
  contactProperties [
    ContactProperties {
      coulombFriction [
        16
      ]
      softCFM 1e-05
      bumpSound ""
      rollSound ""
      slideSound ""
    }
    ContactProperties {
      material1 "SwivelWheelMaterial"
      coulombFriction [
        0.02
      ]
      bounce 0
      softERP 0.4
    }
    ContactProperties {
      material1 "DrivingWheelMaterial"
      coulombFriction [
        0.2
      ]
      bounce 0
      softERP 0.8
      softCFM 0.0001
    }
  ]
}
Viewpoint {
  orientation 0.1463485649752217 0.0032621327267319308 -0.9892277068601378 3.0975277603259155
  position 94.87093414760439 4.657880953919827 20.50926984803317
  follow "Agrobot"
}
TexturedBackground {
}
TexturedBackgroundLight {
}
RectangleArena {
  translation -2.67 0 0
  floorSize 200 200
  floorTileSize 10 10
  wallHeight 10
}
Robot {
  translation -3 1.3 0.5
  children [
    Transform {
      translation 0 0 1
      rotation 1 0 0 1.5708
      scale 0.01 0.01 0.01
      children [
        Shape {
          appearance PBRAppearance {
            baseColor 0.9 0.9 0.9
            roughness 1
            metalness 0
          }
          geometry DEF MY_ROBOT_SHAPE Mesh {
            url [
              "https://raw.githubusercontent.com/tjacobs131/Agrobot/main/resource/agrobot_model.obj"
            ]
          }
        }
      ]
    }
    Pose {
      translation -1 6 9
      rotation 0 -1 0 -1.57081
      children [
        Camera {
          name "detection_camera"
          fieldOfView 0.76
          width 640
          height 480
          far 1000
          recognition Recognition {
            maxRange 1000
            frameColor 0 1 0
            frameThickness 3
          }
        }
      ]
    }
    DEF WHEEL1 HingeJoint {
      jointParameters HingeJointParameters {
        axis 0 1 0
        anchor -3.1 -0.5 1.5
        stopERP 1
        stopCFM 0.01
      }
      device [
        RotationalMotor {
          name "left wheel motor"
          maxVelocity 5000
          maxTorque 800
        }
      ]
      endPoint Solid {
        translation -3.1 -0.5 1.5
        rotation 1 0 0 1.57084
        children [
          DEF WHEEL Shape {
            appearance PBRAppearance {
              baseColor 0.305882 0.898039 0.25098
              roughness 1
              metalness 0
            }
            geometry Cylinder {
              height 1
              radius 2
              subdivision 24
            }
          }
        ]
        contactMaterial "DrivingWheelMaterial"
        boundingObject USE WHEEL
        physics Physics {
          density 300
        }
      }
    }
    DEF WHEEL2 HingeJoint {
      jointParameters HingeJointParameters {
        axis 0 1 0
        anchor -3.1 13.5 1.5
        stopERP 1
        stopCFM 0.01
      }
      device [
        RotationalMotor {
          name "right wheel motor"
          maxVelocity 5000
          maxTorque 800
        }
      ]
      endPoint Solid {
        translation -3.1 13.5 1.5
        rotation 1 0 0 1.5708
        children [
          DEF WHEEL Shape {
            appearance PBRAppearance {
              baseColor 0.305882 0.898039 0.25098
              roughness 1
              metalness 0
            }
            geometry Cylinder {
              height 1
              radius 2
              subdivision 24
            }
          }
        ]
        contactMaterial "DrivingWheelMaterial"
        boundingObject USE WHEEL
        physics Physics {
          density 300
        }
      }
    }
    Solid {
      translation 9.32 -0.5 0.54
      children [
        DEF SWIVEL Shape {
          appearance PBRAppearance {
            baseColor 0.9 0.9 0.9
            roughness 1
            metalness 0
          }
          geometry Sphere {
            radius .8
          }
        }
      ]
      name "swivelWheel1"
      contactMaterial "SwivelWheelMaterial"
      boundingObject USE SWIVEL
      physics Physics {
        mass 5
      }
    }
    Solid {
      translation 9.32 13.5 0.54
      children [
        DEF SWIVEL Shape {
          appearance PBRAppearance {
            baseColor 0.9 0.9 0.9
            roughness 1
            metalness 0
          }
          geometry Sphere {
            radius .8
          }
        }
      ]
      name "swivelWheel2"
      contactMaterial "SwivelWheelMaterial"
      boundingObject USE SWIVEL
      physics Physics {
        mass 5
      }
    }
  ]
  name "Agrobot"
  physics Physics {
    mass 50
  }
  controller "<extern>"
}
PlanterBox {
  translation -27.5 -7.5 1
}
PlanterBox {
  translation -12.5 -7.5 1
}
PlanterBox {
  translation -27.5 7.5 1
}
PlanterBox {
  translation -12.5 7.5 1
}
