#VRML_SIM R2023b utf8

EXTERNPROTO "https://raw.githubusercontent.com/cyberbotics/webots/R2023a/projects/objects/backgrounds/protos/TexturedBackground.proto"
EXTERNPROTO "https://raw.githubusercontent.com/cyberbotics/webots/R2023a/projects/objects/backgrounds/protos/TexturedBackgroundLight.proto"
EXTERNPROTO "https://raw.githubusercontent.com/cyberbotics/webots/R2023a/projects/objects/floors/protos/RectangleArena.proto"
EXTERNPROTO "https://raw.githubusercontent.com/cyberbotics/webots/R2023a/projects/appearances/protos/Pavement.proto"
EXTERNPROTO "../protos/Carrot.proto"
EXTERNPROTO "../protos/Carrot2.proto"

WorldInfo {
  contactProperties [
    ContactProperties {
      softCFM 1e-05
    }
  ]
}
Viewpoint {
  orientation 0.23263009419676942 -0.17481223109735386 -0.9567256258367743 4.388231176945018
  position -0.14763168941498395 -6.548710756235212 4.556739825427911
}
TexturedBackground {
}
TexturedBackgroundLight {
}
RectangleArena {
  floorSize 5 5
  floorTileSize 5 5
  floorAppearance Pavement {
    type "grid"
    colorOverride 0.753 0.753 0.75
  }
}
Robot {
  children [
    DEF base Pose {
      translation -0.15 0.15 0
      rotation 1 0 0 1.5708
      children [
        Shape {
          appearance PBRAppearance {
            baseColor 1 0 0
            metalness 0
          }
          geometry Mesh {
            url [
              "obj/Base_Scaled_Bigger.stl"
            ]
          }
        }
      ]
    }
    DEF shoulder SliderJoint {
      jointParameters JointParameters {
        position 0.3801499939993974
      }
      device [
        DEF arm_motor LinearMotor {
          name "arm_motor"
          maxForce 10000
        }
      ]
      endPoint DEF arm Solid {
        translation 0 0 -0.17499168162426348
        rotation 0 1 0 0
        children [
          DEF arm Pose {
            translation -0.15 0.15 0.4
            rotation -0.5773509358554485 0.5773489358556708 0.5773509358554485 2.0944
            children [
              Shape {
                appearance PBRAppearance {
                  baseColor 0 1 0
                  metalness 0
                }
                geometry Mesh {
                  url [
                    "obj/Arm_Scaled_Bigger.stl"
                  ]
                }
              }
            ]
          }
          DEF wrist HingeJoint {
            jointParameters HingeJointParameters {
              position -5.8760736826594374e-05
              anchor -1.45 0 0.25
            }
            device [
              RotationalMotor {
                name "wrist_motor"
                maxTorque 10000
              }
            ]
            endPoint Solid {
              translation -1.45 0 0.25
              rotation -1 0 0 5.876073352927856e-05
              children [
                DEF wrist Pose {
                  translation 0 -0.2 -0.07
                  rotation 0 0 1 1.5708
                  children [
                    Shape {
                      appearance PBRAppearance {
                        baseColor 0 0.5 1
                        metalness 0
                      }
                      geometry Mesh {
                        url [
                          "obj/Pivot_2Finger_Scaled_Bigger.stl"
                        ]
                      }
                    }
                  ]
                }
                DEF led0 LED {
                  translation -0.02 -0.19 0
                  rotation 1 0 0 1.5708
                  children [
                    Shape {
                      appearance PBRAppearance {
                        baseColor 0.333333 0 0
                        metalness 0
                      }
                      geometry Capsule {
                        height 0.04
                        radius 0.02
                      }
                    }
                  ]
                  name "led0"
                }
                DEF led1 LED {
                  translation -0.02 0.19 0
                  rotation 1 0 0 1.5708
                  children [
                    Shape {
                      appearance PBRAppearance {
                        baseColor 0.333333 0 0
                        metalness 0
                      }
                      geometry Capsule {
                        height 0.04
                        radius 0.02
                      }
                    }
                  ]
                  name "led1"
                }
                DEF finger_R HingeJoint {
                  jointParameters HingeJointParameters {
                    position 0.38764017167162
                    axis 0 0 1
                    anchor -0.12 0.1 0
                  }
                  device [
                    RotationalMotor {
                      name "finger_motor::master"
                      maxTorque 100000
                    }
                  ]
                  endPoint Solid {
                    translation -0.12 0.1 0
                    rotation 0 0 -0.9999999999999999 0.39775513550796116
                    children [
                      DEF finger_right Group {
                        children [
                          Pose {
                            translation 0.08 -0.08 0.05
                            rotation -0.577349935856137 0.5773509358560258 -0.577349935856137 2.09439
                            children [
                              Shape {
                                appearance PBRAppearance {
                                  baseColor 0.9 0 0.6
                                  metalness 0
                                }
                                geometry Mesh {
                                  url [
                                    "obj/Finger_Scaled_Bigger_1.stl"
                                  ]
                                }
                              }
                            ]
                          }
                          Pose {
                            translation 0 0 -0.07
                            children [
                              Shape {
                                appearance PBRAppearance {
                                  baseColor 0 0 0
                                  metalness 0
                                }
                                geometry Mesh {
                                  url [
                                    "obj/Pin_Scaled_Bigger.stl"
                                  ]
                                }
                              }
                            ]
                          }
                        ]
                      }
                    ]
                    boundingObject Group {
                      children [
                        Pose {
                          translation -0.312 0.024 0
                          rotation 0 0 1 -0.139
                          children [
                            Shape {
                              geometry Box {
                                size 0.5 0.14 0.1
                              }
                            }
                          ]
                        }
                        Pose {
                          translation -0.716 0.007 0
                          rotation 0 0 1 0.24
                          children [
                            Shape {
                              geometry Box {
                                size 0.34 0.1 0.1
                              }
                            }
                          ]
                        }
                      ]
                    }
                    physics Physics {
                      mass 1
                    }
                  }
                }
                DEF finger_L HingeJoint {
                  jointParameters HingeJointParameters {
                    position -0.17145670573515503
                    axis 0 0 1
                    anchor -0.12 -0.1 0
                  }
                  device [
                    RotationalMotor {
                      name "finger_motor::slave"
                      maxTorque 100000
                      multiplier -1
                    }
                  ]
                  endPoint Solid {
                    translation -0.12 -0.1 0
                    rotation 0 0 1 0.6139486014443557
                    children [
                      DEF finger_left Group {
                        children [
                          Pose {
                            translation 0.08 0.08 -0.05
                            rotation 0.5773509358554485 0.5773489358556708 0.5773509358554485 2.0944
                            children [
                              Shape {
                                appearance PBRAppearance {
                                  baseColor 0.9 0 0.6
                                  metalness 0
                                }
                                geometry Mesh {
                                  url [
                                    "obj/Finger_Scaled_Bigger_2.stl"
                                  ]
                                }
                              }
                            ]
                          }
                          Pose {
                            translation 0 0 -0.07
                            children [
                              Shape {
                                appearance PBRAppearance {
                                  baseColor 0 0 0
                                  metalness 0
                                }
                                geometry Mesh {
                                  url [
                                    "obj/Pin_Scaled_Bigger.stl"
                                  ]
                                }
                              }
                            ]
                          }
                        ]
                      }
                    ]
                    name "solid(1)"
                    boundingObject Group {
                      children [
                        Pose {
                          translation -0.312 -0.024 0
                          rotation 0 0 1 0.139
                          children [
                            Shape {
                              geometry Box {
                                size 0.5 0.14 0.1
                              }
                            }
                          ]
                        }
                        Pose {
                          translation -0.716 -0.007 0
                          rotation 0 0 1 -0.24
                          children [
                            Shape {
                              geometry Box {
                                size 0.34 0.1 0.1
                              }
                            }
                          ]
                        }
                      ]
                    }
                    physics Physics {
                      mass 1
                    }
                  }
                }
              ]
              boundingObject Pose {
                translation -0.05 0 0
                children [
                  Shape {
                    geometry Box {
                      size 0.1 0.4 0.14
                    }
                  }
                ]
              }
              physics Physics {
                mass 1
              }
            }
          }
        ]
        boundingObject Pose {
          translation -0.8 0 0.25
          children [
            Shape {
              geometry Box {
                size 1.3 0.3 0.3
              }
            }
          ]
        }
        physics Physics {
          mass 1
        }
      }
    }
    DistanceSensor {
      translation -2.42 0.18 -0.025
      rotation 0 1 0 -1.57
      children [
        Shape {
          appearance PBRAppearance {
            baseColor 1 0.5 0.5
            metalness 0
          }
          geometry Box {
            size 0.05 0.05 0.05
          }
        }
      ]
      name "ds_centre"
      lookupTable [
        0 0 0
        1 1000 0
        2 2000 0
      ]
      type "infra-red"
      aperture 0
      resolution 0.001
    }
  ]
  boundingObject Pose {
    translation 0 0 1
    children [
      Shape {
        geometry Box {
          size 0.3 0.3 2
        }
      }
    ]
  }
  controller "two_finger_gripper_controller"
  supervisor TRUE
}
DEF redbox Solid {
  translation -1.1996793096855376 -4.022395137701619e-05 -0.009153796635319955
  rotation 0.19986549602308856 0.9777116431222224 0.064294061955118 0.0009691034565655628
  children [
    DEF redbox Shape {
      appearance Appearance {
        material Material {
          diffuseColor 1 0 0
        }
      }
      geometry Box {
        size 0.25 0.25 0.25
      }
    }
  ]
  name "redbox"
  contactMaterial "box"
  boundingObject USE redbox
  physics Physics {
    mass 50
  }
}
Carrot {
  solidTranslation -4 -0.05 0
  BObjectTranslation -4 -0.05 -0.5
  BObjectHeight 3
  bodyMass 100
}
Carrot2 {
  solidTranslation -2.15 -0.05 0
  BObjectTranslation -2.15 -0.05 0
  boxSize 0.45 0.45 0.45
}
