#VRML_SIM R2022b utf8

EXTERNPROTO "https://raw.githubusercontent.com/cyberbotics/webots/R2022b/projects/objects/backgrounds/protos/TexturedBackground.proto"
EXTERNPROTO "https://raw.githubusercontent.com/cyberbotics/webots/R2022b/projects/objects/backgrounds/protos/TexturedBackgroundLight.proto"
EXTERNPROTO "https://raw.githubusercontent.com/cyberbotics/webots/R2023b/projects/objects/floors/protos/Floor.proto"
IMPORTABLE EXTERNPROTO "../protos/PlanterBox.proto"

WorldInfo {
}
Viewpoint {
  orientation -0.33185733874619844 -0.09874274160469809 0.9381474178937331 3.686018050088086
  position 1.700313773507203 1.0549607538959629 3.4846240848267684
  follow "Agrobot"
}
TexturedBackground {
}
TexturedBackgroundLight {
}
Floor {
  size 10000 10000
}
Robot {
  children [
    Transform {
      translation 0 0 50
      scale .1 .1 .1
      rotation 1 0 0 1.5708
      children [
        Shape {
          appearance PBRAppearance {
            baseColor 0.9 0.9 0.9
            roughness 1
            metalness 0
          }
          geometry DEF MY_ROBOT_SHAPE Mesh {
            url "../resource/agrobot_model.obj"
          }
        }
      ]
    }
    DEF WHEEL1 HingeJoint {
      jointParameters HingeJointParameters {
        axis 0 1 0
        anchor 0.05 0.06 0
      }
      device [
        RotationalMotor {
          name "wheel1"
        }
      ]
      endPoint Solid {
        translation 0.05 0.06 0
        rotation 1 0 0 1.5708
        children [
          DEF WHEEL Shape {
            appearance PBRAppearance {
              baseColor 0.305882 0.898039 0.25098
              roughness 1
              metalness 0
            }
            geometry Cylinder {
              height 0.02
              radius 0.04
              subdivision 24
            }
          }
        ]
        boundingObject USE WHEEL
        physics Physics {
        }
      }
    }
  ]
  boundingObject USE MY_ROBOT_SHAPE
  physics Physics {
    
  }
  controller "<extern>"
  name "Agrobot"
}
PlanterBox {
  translation -75 -75 2
}
PlanterBox {
  translation 75 -75 2
}
PlanterBox {
  translation -75 75 2
}
PlanterBox {
  translation 75 75 2
}